Workbook

Sheet ABB (2)
A1: 宁波海越电器制造有限公司
A2: 产 品 报 价 单
A4: 项目名称：南岸服务区电力改造工程
A5: 产品名称：配电设备 电话： 报价单号：HY2601-0029
A6: 产品型号： 传真： 联系人：
A7: 序号 | B7: 名 称 | C7: 型 号 | D7: 单位 | E7: 数量 | F7: 单价(元) | G7: 金额(元)
A8: 1 | B8: 低压出线柜3D4 3D5 4D3 4D4 4D6 4D7 5D4 5D5 6D3 6D4 6D6 6D7 | C8: GCS | D8: 台 | E8: 12 | F8: =ROUND(H8,0) -> 39861 | G8: =E8*F8 -> 478332 | H8: =F55 -> 39861
A9: 2
A10: 3
A11: 4
A12: 5
A13: 6
A14: 7
A15: 8
A16: 9
A17: 10
A18: 合计 | B18: =G18 -> 478332 | G18: =SUM(G8:G17) -> 478332 | H18: 2155028 | N18: =H18/G18 -> 4.5052976 | O18: =G18*1.2 -> 573998.4 | P18: =H18*0.73 -> 1573170.4 | Q18: =P18/G18 -> 3.2888672 | R18: =G18/H18 -> 0.22196092
A19: 报价备注 | B19: 1、以上报价含13%增值税，含运费； | H19: =#REF!-G18 -> #REF!
B20: 2、气体绝缘环网柜采用施耐德公司产品；
B21: 3、高压真空断路器、低压断路器均采用ABB公司产品；
B22: 4、微机保护装置、数显仪表均采用宁波美格电力自动化工程有限公司产品；
B23: 5、电容电抗器采用台州安耐杰电力设备有限公司产品；
B24: 6、所有电器连接均采用含铜99.9%的纯铜连接；
B25: 7、产品质量免费保修壹年，终身服务。
A26: 报价日期：2026年1月28日 有效期：30天 报价：洪辉 审核:袁剑幸
A28: 地址：宁波市镇海骆驼机电园区盛兴路348号
A29: 电话：0574-86595601、86595616
A30: 传真：0574-86595600 联系人:陆建德 13884410385
A31: E-mail：info@nbhaiyue.com
A32: 宁波海越电器制造有限公司
A33: 报 价 明 细 表
A35: =B8 -> 低压出线柜3D4 3D5 4D3 4D4 4D6 4D7 5D4 5D5 6D3 6D4 6D6 6D7
A36: 序号 | B36: 名 称 | C36: 型 号 | D36: 数量(只) | E36: 单价(元) | F36: 金额(元) | G36: 产地/品牌 | I36: 电流 | J36: 总电缆费用 | K36: 柜宽 | L36: 电流 | M36: 铜排规格
A37: 1 | B37: 塑壳断路器 | C37: XT1N160 TMD 63 3P FF | D37: 0 | E37: =ROUND(H37,0) -> 444 | F37: =E37*D37 -> 0 | G37: =VLOOKUP(C37,库!A:D,4,FALSE()) -> ABB | H37: =VLOOKUP(C37,库!A:D,3,FALSE()) -> 443.754 | I37: =63*D37 -> 0 | J37: =80*D37*((K39/105-1)/2+1) -> 0 | K37: 0.8 | L37: 500 | M37: 0.18 | N37: =D37*166 -> 0 | O37: =400*D37 -> 0 | P37: =IF(F37<10000,F37*0.3,IF(F37>49999.99,F37*0.1,(0.29-0.000003125*F37)*F37)) -> 0
A38: 2 | B38: 塑壳断路器 | C38: XT1N160 TMD 100 3P FF | D38: 1 | E38: =ROUND(H38,0) -> 444 | F38: =E38*D38 -> 444 | G38: =VLOOKUP(C38,库!A:D,4,FALSE()) -> ABB | H38: =VLOOKUP(C38,库!A:D,3,FALSE()) -> 443.754 | I38: =100*D38 -> 100 | J38: =120*D38*((K39/105-1)/2+1) -> 117.14286 | K38: 铜价 | L38: 755 | M38: 0.24 | N38: =D38*166 -> 166 | O38: =400*D38 -> 400 | P38: =IF(F38<10000,F38*0.3,IF(F38>49999.99,F38*0.1,(0.29-0.000003125*F38)*F38)) -> 133.2
A39: 3 | B39: 塑壳断路器 | C39: XT1N160 TMD 160 3P FF | D39: 2 | E39: =ROUND(H39,0) -> 737 | F39: =E39*D39 -> 1474 | G39: =VLOOKUP(C39,库!A:D,4,FALSE()) -> ABB | H39: =VLOOKUP(C39,库!A:D,3,FALSE()) -> 736.794 | I39: =160*D39 -> 320 | J39: =120*D39*((K39/105-1)/2+1) -> 234.28571 | K39: 100 | L39: 990 | M39: 0.36 | N39: =D39*340 -> 680 | O39: =400*D39 -> 800 | P39: =IF(F39<10000,F39*0.3,IF(F39>49999.99,F39*0.1,(0.29-0.000003125*F39)*F39)) -> 442.2
A40: 4 | B40: 塑壳断路器 | C40: XT3N250 TMD 250 3P FF | D40: 2 | E40: =ROUND(H40,0) -> 1056 | F40: =E40*D40 -> 2112 | G40: =VLOOKUP(C40,库!A:D,4,FALSE()) -> ABB | H40: =VLOOKUP(C40,库!A:D,3,FALSE()) -> 1055.538 | I40: =D40*250 -> 500 | J40: =192*D40*((K39/105-1)/2+1) -> 374.85714 | L40: 1160 | M40: 0.48 | N40: =D40*192 -> 384 | O40: =400*D40 -> 800 | P40: =IF(F40<10000,F40*0.3,IF(F40>49999.99,F40*0.1,(0.29-0.000003125*F40)*F40)) -> 633.6
A41: 5 | B41: 塑壳断路器 | C41: XT5N400 TMA 400 3P FF | D41: 0 | E41: =ROUND(H41,0) -> 1579 | F41: =E41*D41 -> 0 | G41: =VLOOKUP(C41,库!A:D,4,FALSE()) -> ABB | H41: =VLOOKUP(C41,库!A:D,3,FALSE()) -> 1578.726 | I41: =D41*400 -> 0 | J41: =192*D41*((K39/105-1)/2+1) -> 0 | L41: 1500 | M41: 0.6 | N41: =D41*192 -> 0 | O41: =400*D41 -> 0 | P41: =IF(F41<10000,F41*0.3,IF(F41>49999.99,F41*0.1,(0.29-0.000003125*F41)*F41)) -> 0
A42: 6 | B42: 塑壳断路器 | C42: XT5N630 TMA 500 3P FF | D42: 0 | E42: =ROUND(H42,0) -> 2960 | F42: =E42*D42 -> 0 | G42: =VLOOKUP(C42,库!A:D,4,FALSE()) -> ABB | H42: =VLOOKUP(C42,库!A:D,3,FALSE()) -> 2960.451 | I42: =D42*500 -> 0 | J42: =401*D42*((K39/105-1)/2+1) -> 0 | M42: 0.72 | N42: =D42*192 -> 0 | O42: =400*D42 -> 0 | P42: =IF(F42<10000,F42*0.3,IF(F42>49999.99,F42*0.1,(0.29-0.000003125*F42)*F42)) -> 0
A43: 7 | B43: 塑壳断路器 | C43: XT5N630 TMA 630 3P FF | D43: 0 | E43: =ROUND(H43,0) -> 3746 | F43: =E43*D43 -> 0 | G43: =VLOOKUP(C43,库!A:D,4,FALSE()) -> ABB | H43: =VLOOKUP(C43,库!A:D,3,FALSE()) -> 3745.7505 | I43: =630*D43 -> 0 | J43: =401*D43*((K39/105-1)/2+1) -> 0 | N43: =D43*192 -> 0 | O43: =400*D43 -> 0 | P43: =IF(F43<10000,F43*0.3,IF(F43>49999.99,F43*0.1,(0.29-0.000003125*F43)*F43)) -> 0
...

Sheet 库
A1: 型号 | B1: 名称 | C1: 单价 | D1: 产地/厂家 | E1: 面价 | F1: 附件 | G1: 折扣 | H1: 板前 | I1: 分励 | J1: 辅助 | K1: 报警 | L1: 电动机保护 | M1: 插入式板后
A2: 2*Mkk480-D-01/B44066D7050 | B2: 电容电抗 | C2: 11500 | D2: 爱普科斯
A3: SJ2206HA2BAL | B3: 风机 | C3: 220 | D3: 台湾/三巨
A4: 3AE-EP 12KV-630A-31.5KA 手车式 | B4: 真空断路器 | C4: 35764 | D4: 西门子
A5: 3AJ1-12 630A-25手车式 | B5: 真空断路器 | C5: 27800 | D5: 西门子
A6: 3AS4-12 1250-31.5手车式 | B6: 真空断路器 | C6: 28000 | D6: 伊顿
A7: 3AS4-12 630-25手车式 | B7: 真空断路器 | C7: 26000 | D7: 伊顿
A9: 3VL400N400 TM PB/3340 螺钉端子 | B9: 塑壳断路器 | C9: =5678*0.7*0.95 -> 3775.87 | D9: 西门子 | E9: =7099*0.58 -> 4117.42
A10: 3VL630H630 TM PB/3340 螺钉端子 | B10: 塑壳断路器 | C10: =9064*0.7*0.95 -> 6027.56 | D10: 西门子 | E10: =10963*0.58 -> 6358.54
A11: 3VL630H630 TM PB/3P 螺钉端子 | B11: 塑壳断路器 | C11: =8489*0.7*0.95 -> 5645.185 | D11: 西门子 | E11: =10368*0.58 -> 6013.44
A12: 3WL1N08 ETU45B 抽屉电动 | B12: 框架断路器 | C12: =45092*0.6*0.95 -> 25702.44 | D12: 西门子 | E12: =48424*0.54 -> 26148.96
A13: 3WL1N10 ETU45B 抽屉电动 | B13: 框架断路器 | C13: =48000*0.6*0.95 -> 27360 | D13: 西门子 | E13: =51452*0.54 -> 27784.08
A14: 3WL1N12 ETU45B 抽屉电动 | B14: 框架断路器 | C14: =50043*0.6*0.95 -> 28524.51 | D14: 西门子 | E14: =53578*0.54 -> 28932.12
A15: 3WL2N20 ETU45B 抽屉电动 | B15: 框架断路器 | C15: =63837*0.6*0.95 -> 36387.09 | D15: 西门子 | E15: =69855*0.54 -> 37721.7
A16: 42L6-A | B16: 电流表 | C16: 21 | D16: 宁波/电子
A17: 42L6-COS | B17: 功率因数表 | C17: 65 | D17: 宁波/电子
A18: 42L6-V | B18: 电压表 | C18: 21 | D18: 宁波/电子
A19: 42L6-V 10/0.1KV | B19: 电压表 | C19: 21 | D19: 宁波/电子
A20: 42L6-W | B20: 功率表 | C20: 80 | D20: 宁波/电子
A21: 6L2-A | B21: 电流表 | C21: 17 | D21: 宁波/电子
A22: 6L2-COS | B22: 功率因素表 | C22: 65 | D22: 宁波/电子
A23: 6L2-V | B23: 电压表 | C23: 17 | D23: 宁波/电子
A24: 6L2-W | B24: 功率表 | C24: 80 | D24: 宁波/电子
A25: 99T1-A | B25: 电流表 | C25: 17 | D25: 宁波/电子
A26: A1-270# | B26: 计量表架 | C26: 23 | D26: 海盐/同安 | G26: =2060*0.65 -> 1339
A27: A-APF/4L-100A C | B27: 有源滤波器 | C27: 158000 | D27: 南京/亚派
A28: A-APF/4L-150A C | B28: 有源滤波器 | C28: 237000 | D28: 南京/亚派
A29: ACR120EL | B29: 数显仪表 | C29: =2000*0.65 -> 1300 | D29: 上海/安科瑞
A30: ACR210EL | B30: 数显仪表 | C30: =1400*0.65 -> 910 | D30: 上海/安科瑞
A31: ACR220EL | B31: 数显仪表 | C31: =2000*0.65 -> 1300 | D31: 上海/安科瑞
A32: ACR220ELH | B32: 数显仪表 | C32: =3200*0.65 -> 2080 | D32: 上海/安科瑞
A33: ACR230ELH | B33: 数显仪表 | C33: =3600*0.65 -> 2340 | D33: 上海/安科瑞
A34: ACR330ELH | B34: 数显仪表 | C34: =3600*0.65 -> 2340 | D34: 上海/安科瑞
A35: Acuvim387 | B35: 数显仪表 | C35: 1600 | D35: 北京/爱博
A36: Acuvim-390 | B36: 数显仪表 | C36: 2200 | D36: 北京/爱博
A37: Acuvim-CL | B37: 数显仪表 | C37: 2640 | D37: 北京/爱博
A38: AcuvimII | B38: 数显仪表 | C38: 3200 | D38: 北京/爱博
A40: AL2D 480V 100KVAR+XKIB 74/400/6-50 | B40: 电容器 | C40: 11815 | D40: 芬兰/诺基亚
A41: AL2D 480V 50KVAR+XKIB 37/400/6-50 | B41: 电容器 | C41: 8550 | D41: 芬兰/诺基亚
A42: ALP08 | B42: 电容器 | C42: 5138 | D42: 阿尔卑斯
...
